{"name": "test_failure", "status": "skipped", "statusDetails": {"message": "XFAIL\n\nAssertionError: assert 1 == 2", "trace": "@pytest.mark.xfail  # func, expected to be failedï¼Œxfailed\n    def test_failure():\n>       assert 1 == 2\nE       assert 1 == 2\n\nunit_tests/test_add.py:26: AssertionError"}, "attachments": [{"name": "log", "source": "ed4ebe47-809e-4662-ad06-c26b7ab67736-attachment.txt", "type": "text/plain"}], "start": 1750369304749, "stop": 1750369304749, "uuid": "4c9efd3c-37f1-4ea0-bc3d-c91f36638622", "historyId": "2534e2cec6a9c4dd05d6592b5699253f", "testCaseId": "2534e2cec6a9c4dd05d6592b5699253f", "fullName": "unit_tests.test_add#test_failure", "labels": [{"name": "parentSuite", "value": "unit_tests"}, {"name": "suite", "value": "test_add"}, {"name": "host", "value": "ubuntu"}, {"name": "thread", "value": "6086-MainThread"}, {"name": "framework", "value": "pytest"}, {"name": "language", "value": "cpython3"}, {"name": "package", "value": "unit_tests.test_add"}]}