{"name": "test_rerun", "status": "failed", "statusDetails": {"message": "AssertionError: assert 1 >= 5", "trace": "@pytest.mark.ut\n    def test_rerun():\n        x = random.randint(0, 9)  # 每次都有随机数出现 generate a random int\n>       assert x >= 5\nE       assert 1 >= 5\n\nunit_tests/test_rerun.py:8: AssertionError"}, "attachments": [{"name": "log", "source": "e12441a9-11c7-412c-8171-c4f34631aaf9-attachment.txt", "type": "text/plain"}], "start": 1750463947065, "stop": 1750463947065, "uuid": "fc1a4c61-f7a7-41d6-9254-39dc0272c0e8", "historyId": "d88f479ac2ebb77bee7c53ff4a1a3cf3", "testCaseId": "d88f479ac2ebb77bee7c53ff4a1a3cf3", "fullName": "unit_tests.test_rerun#test_rerun", "labels": [{"name": "tag", "value": "ut"}, {"name": "parentSuite", "value": "unit_tests"}, {"name": "suite", "value": "test_rerun"}, {"name": "host", "value": "mb5"}, {"name": "thread", "value": "59509-MainThread"}, {"name": "framework", "value": "pytest"}, {"name": "language", "value": "cpython3"}, {"name": "package", "value": "unit_tests.test_rerun"}]}