{"name": "test_rerun", "status": "failed", "statusDetails": {"message": "AssertionError: assert 2 >= 5", "trace": "@pytest.mark.ut\n    def test_rerun():\n        x = random.randint(0, 9)  # 每次都有随机数出现 generate a random int\n>       assert x >= 5\nE       assert 2 >= 5\n\nunit_tests/test_rerun.py:8: AssertionError"}, "attachments": [{"name": "log", "source": "93dd76f7-a44c-48be-8916-7bbd38ad1337-attachment.txt", "type": "text/plain"}], "start": 1750350693933, "stop": 1750350693933, "uuid": "c75cc267-7f2a-483d-abc9-c86a23d60a3b", "historyId": "d88f479ac2ebb77bee7c53ff4a1a3cf3", "testCaseId": "d88f479ac2ebb77bee7c53ff4a1a3cf3", "fullName": "unit_tests.test_rerun#test_rerun", "labels": [{"name": "tag", "value": "ut"}, {"name": "parentSuite", "value": "unit_tests"}, {"name": "suite", "value": "test_rerun"}, {"name": "host", "value": "ubuntu"}, {"name": "thread", "value": "32592-MainThread"}, {"name": "framework", "value": "pytest"}, {"name": "language", "value": "cpython3"}, {"name": "package", "value": "unit_tests.test_rerun"}]}