{"name": "test_rerun", "status": "failed", "statusDetails": {"message": "AssertionError: assert 0 >= 5", "trace": "@pytest.mark.ut\n    def test_rerun():\n        x = random.randint(0, 9)  # 每次都有随机数出现 generate a random int\n>       assert x >= 5\nE       assert 0 >= 5\n\nunit_tests/test_rerun.py:8: AssertionError"}, "attachments": [{"name": "log", "source": "47ea5bab-2d47-42b9-835f-d6e9cc321c07-attachment.txt", "type": "text/plain"}], "start": 1750465683371, "stop": 1750465683371, "uuid": "292b7078-8834-4de5-9a1e-67f93f57b0a6", "historyId": "d88f479ac2ebb77bee7c53ff4a1a3cf3", "testCaseId": "d88f479ac2ebb77bee7c53ff4a1a3cf3", "fullName": "unit_tests.test_rerun#test_rerun", "labels": [{"name": "tag", "value": "ut"}, {"name": "parentSuite", "value": "unit_tests"}, {"name": "suite", "value": "test_rerun"}, {"name": "host", "value": "mb5"}, {"name": "thread", "value": "65672-MainThread"}, {"name": "framework", "value": "pytest"}, {"name": "language", "value": "cpython3"}, {"name": "package", "value": "unit_tests.test_rerun"}]}