{"name": "test_failure", "status": "skipped", "statusDetails": {"message": "XFAIL\n\nAssertionError: assert 1 == 2", "trace": "@pytest.mark.xfail  # func, expected to be failedï¼Œxfailed\n    def test_failure():\n>       assert 1 == 2\nE       assert 1 == 2\n\nunit_tests/test_add.py:26: AssertionError"}, "attachments": [{"name": "log", "source": "8c8fb553-2bf6-4041-b6a1-4c9a77467a96-attachment.txt", "type": "text/plain"}], "start": 1750350693899, "stop": 1750350693899, "uuid": "24b0054b-182f-4029-8baa-f26e06f753e1", "historyId": "2534e2cec6a9c4dd05d6592b5699253f", "testCaseId": "2534e2cec6a9c4dd05d6592b5699253f", "fullName": "unit_tests.test_add#test_failure", "labels": [{"name": "parentSuite", "value": "unit_tests"}, {"name": "suite", "value": "test_add"}, {"name": "host", "value": "ubuntu"}, {"name": "thread", "value": "32592-MainThread"}, {"name": "framework", "value": "pytest"}, {"name": "language", "value": "cpython3"}, {"name": "package", "value": "unit_tests.test_add"}]}