{"name": "test_failure", "status": "skipped", "statusDetails": {"message": "XFAIL\n\nAssertionError: assert 1 == 2", "trace": "@pytest.mark.xfail  # func, expected to be failedï¼Œxfailed\n    def test_failure():\n>       assert 1 == 2\nE       assert 1 == 2\n\nunit_tests/test_add.py:26: AssertionError"}, "attachments": [{"name": "log", "source": "011d1cb7-01d9-4e12-8dc2-9d98cb4f1b1a-attachment.txt", "type": "text/plain"}], "start": 1750463947003, "stop": 1750463947003, "uuid": "2126f5e9-0244-4710-a0ad-ad40731bca70", "historyId": "2534e2cec6a9c4dd05d6592b5699253f", "testCaseId": "2534e2cec6a9c4dd05d6592b5699253f", "fullName": "unit_tests.test_add#test_failure", "labels": [{"name": "parentSuite", "value": "unit_tests"}, {"name": "suite", "value": "test_add"}, {"name": "host", "value": "mb5"}, {"name": "thread", "value": "59509-MainThread"}, {"name": "framework", "value": "pytest"}, {"name": "language", "value": "cpython3"}, {"name": "package", "value": "unit_tests.test_add"}]}