{"name": "test_failure", "status": "skipped", "statusDetails": {"message": "XFAIL\n\nAssertionError: assert 1 == 2", "trace": "@pytest.mark.xfail  # func, expected to be failedï¼Œxfailed\n    def test_failure():\n>       assert 1 == 2\nE       assert 1 == 2\n\nunit_tests/test_add.py:26: AssertionError"}, "attachments": [{"name": "log", "source": "2bbc3815-4aec-4929-a16c-c7dce68a73a5-attachment.txt", "type": "text/plain"}], "start": 1750465683310, "stop": 1750465683310, "uuid": "f7691708-5206-430b-8083-ba9e31eecbbf", "historyId": "2534e2cec6a9c4dd05d6592b5699253f", "testCaseId": "2534e2cec6a9c4dd05d6592b5699253f", "fullName": "unit_tests.test_add#test_failure", "labels": [{"name": "parentSuite", "value": "unit_tests"}, {"name": "suite", "value": "test_add"}, {"name": "host", "value": "mb5"}, {"name": "thread", "value": "65672-MainThread"}, {"name": "framework", "value": "pytest"}, {"name": "language", "value": "cpython3"}, {"name": "package", "value": "unit_tests.test_add"}]}