{"name": "test_failure", "status": "skipped", "statusDetails": {"message": "XFAIL\n\nAssertionError: assert 1 == 2", "trace": "@pytest.mark.xfail  # func, expected to be failedï¼Œxfailed\n    def test_failure():\n>       assert 1 == 2\nE       assert 1 == 2\n\nunit_tests\\test_add.py:26: AssertionError"}, "attachments": [{"name": "log", "source": "a19a478d-4f66-43a8-b018-dfc0b7e720f5-attachment.txt", "type": "text/plain"}], "start": 1749841919133, "stop": 1749841919133, "uuid": "5c82a6f6-75f7-4a25-a512-9ea2bfb1f745", "historyId": "2534e2cec6a9c4dd05d6592b5699253f", "testCaseId": "2534e2cec6a9c4dd05d6592b5699253f", "fullName": "unit_tests.test_add#test_failure", "labels": [{"name": "parentSuite", "value": "unit_tests"}, {"name": "suite", "value": "test_add"}, {"name": "host", "value": "Novele"}, {"name": "thread", "value": "26108-MainThread"}, {"name": "framework", "value": "pytest"}, {"name": "language", "value": "cpython3"}, {"name": "package", "value": "unit_tests.test_add"}]}