WARNING  pytest_result_log:plugin.py:122 ------------------Start: unit_tests/test_add.py::test_success-------------------
WARNING  pytest_result_log:plugin.py:128 -------------------End: unit_tests/test_add.py::test_success--------------------